Workbook

Sheet META-DATA
E2: PROJECT NAME >>> | F2: 2018_UnivMD_Maryland_86896 | K2: DO NOT TYPE IN ANY YELLOW BOX | V2: =TEXT(MIN(V10:V105),"yyyymmdd") -> 20180711 | W2: Calculated Earliest Start Date
E3: DEPLOYMENT >>> | F3: 1 | K3: RED BOXES REQUIRE INPUT | V3: =RIGHT("00"&$F$3,2) -> 01 | W3: Calculated Deployment Number
E4: FIELD OPERATIONS TECHNICIAN >>> | F4: FRC29 | I4: DATA ENTRY | J4: FRC29 | R4: SOURCE FOR DEPTH : | S4: ( C ) IF FROM A CHART | X4: Time Zone : | Y4: RECORD ALL TIMES IN OFFSET FROM UTC | AB4: Example: UTC = 0, EST = -5, EDT = -4
B5: RECORDER TYPE : | C5: V2.5 Popup | M5: DUTY CYCLE: | N5: ( 0 ) IF CONTINOUS RECORDINGS | S5: ( S ) IF FROM A BOTTOM SOUNDER | Y5: IF TIME IS RECORDED DIFFERENTLY IN DECK NOTES,
C6: AMAR | N6: ( SECONDS ) IF DUTY CYCLED | S6: ( G ) IF FROM GOOGLE EARTH | Y6: CONVERT TO UTC PRIOR TO RECORDING ON THIS SHEET
C7: ROCKHOPPER | S7: ( H ) IF FROM HISTORICAL DATA (PREVIOUS DEPLOYMENT) | Y7: AND INSERT DETAILS IN THE COMMENTS SECTION
A8: ARRAY ID | B8: Recorder Type | C8: UNIT # | D8: Medium Type | E8: DRIVE # 1 | F8: DRIVE # 2 | G8: SITE ID | H8: FREQ, kHz | I8: FREQ Hz | J8: Filter, High Pass Hz | K8: Filter, Low Pass Hz | L8: Gain dB | M8: DUTY CYCLE seconds on | N8: DUTY CYCLE seconds off | O8: DROP LAT Decimal Degrees | P8: DROP LON Decimal Degrees | Q8: DEPTH IN METERS | R8: SOURCE FOR DEPTH | S8: ARGOS # | T8: XEOS ID | U8: FREQUENCY | V8: RECORD START DATE | W8: RECORD START TIME (<1sec accuracy) | X8: RECORD START TIME ZONE | Y8: DROP DATE | Z8: DROP TIME (1min accuracy) | AA8: Drop TIME ZONE | AB8: RETRIEVAL DATE | AC8: ON DECK TIME (5min accuracy) | AD8: Retrieval TIME ZONE | AE8: DISCONNECT DATE | AF8: DISCONNECT TIME (1min accuracy) | AG8: Shut Down TIME ZONE | AH8: Burn Date Set | AI8: Burn Time Set | AJ8: Burn TIME ZONE | AK8: COMMENT | AL8: PROJECT NAME
A9: SAMPLE DATA | B9: V2.5 Popup | C9: 999 | D9: CompactFlash | E9: 9902 | F9: 9904 | G9: X1 | H9: 2 | I9: 2000 | J9: 10 | K9: 800 | L9: 23.5 | M9: 0 | N9: 0 | O9: 41.2499 | P9: -70.3895 | Q9: 14 | R9: C | S9: 128045 | T9: xxx | U9: 151.818 | V9: 42355 | W9: 0.63665509 | X9: 0 | Y9: 42355 | Z9: 0.55416667 | AA9: 0 | AB9: 42522 | AC9: 0.37152778 | AD9: 0 | AE9: 42522 | AF9: 0.58680556 | AG9: 0 | AH9: 42623 | AI9: 0.67796296 | AJ9: 0 | AK9: THIS IS SAMPLE DATA - DO NOT CHANGE | AL9: =$F$2&"_Dep"&$V$3&"_"&$V$2 -> 2018_UnivMD_Maryland_86896_Dep01_20180711
A10: UMD | B10: V2.5 Popup | C10: 168 | D10: CompactFlash | E10: 3164 | G10: M1 | H10: 16 | I10: 16000 | J10: 10 | K10: 6400 | L10: 23.5 | M10: 0 | N10: 0 | O10: 38.37031 | P10: -74.75384 | Q10: 27 | R10: S | S10: 134121 | V10: 43292 | W10: 0.52575231 | X10: 0 | Y10: 43293 | Z10: 0.71041667 | AA10: 0 | AB10: 43333 | AC10: 0.52916667 | AD10: 0 | AH10: 43388 | AI10: 0.55084491 | AJ10: 0 | AL10: =$F$2&"_Dep"&$V$3&"_"&$V$2 -> 2018_UnivMD_Maryland_86896_Dep01_20180711
A11: UMD | B11: V2.5 Popup | C11: 89 | D11: CompactFlash | E11: 3156 | G11: M2 | H11: 16 | I11: 16000 | J11: 10 | K11: 6400 | L11: 23.5 | M11: 0 | N11: 0 | O11: 38.35305 | P11: -74.7309 | Q11: 27 | R11: S | S11: 134136 | V11: 43292 | W11: 0.53015046 | X11: 0 | Y11: 43293 | Z11: 0.71805556 | AA11: 0 | AB11: 43333 | AC11: 0.55277778 | AD11: 0 | AH11: 43388 | AI11: 0.59321759 | AJ11: 0 | AK11: CTD# S7958 | AL11: =$F$2&"_Dep"&$V$3&"_"&$V$2 -> 2018_UnivMD_Maryland_86896_Dep01_20180711
A12: UMD | B12: V2.5 Popup | C12: 188 | D12: CompactFlash | E12: 3168 | G12: M3 | H12: 16 | I12: 16000 | J12: 10 | K12: 6400 | L12: 23.5 | M12: 0 | N12: 0 | O12: 38.33452 | P12: -74.75369 | Q12: 25 | R12: S | S12: 134126 | V12: 43292 | W12: 0.53385417 | X12: 0 | Y12: 43293 | Z12: 0.69583333 | AA12: 0 | AB12: 43333 | AC12: 0.48125 | AD12: 0 | AH12: 43388 | AI12: 0.63559028 | AJ12: 0 | AK12: CTD# S8044 SURFACED EARLY, RECOVERED ON RETRIEVAL DAY | AL12: =$F$2&"_Dep"&$V$3&"_"&$V$2 -> 2018_UnivMD_Maryland_86896_Dep01_20180711
A13: UMD | B13: V2.5 Popup | C13: 142 | D13: CompactFlash | E13: 3104 | G13: M4 | H13: 16 | I13: 16000 | J13: 10 | K13: 6400 | L13: 23.5 | M13: 0 | N13: 0 | O13: 38.35279 | P13: -74.77635 | Q13: 28 | R13: S | S13: 134132 | V13: 43292 | W13: 0.52060185 | X13: 0 | Y13: 43293 | Z13: 0.70347222 | AA13: 0 | AB13: 43333 | AC13: 0.57430556 | AD13: 0 | AH13: 43388 | AI13: 0.50847222 | AJ13: 0 | AK13: CTD# S7959 | AL13: =$F$2&"_Dep"&$V$3&"_"&$V$2 -> 2018_UnivMD_Maryland_86896_Dep01_20180711
AL14: =$F$2&"_Dep"&$V$3&"_"&$V$2 -> 2018_UnivMD_Maryland_86896_Dep01_20180711
AL15: =$F$2&"_Dep"&$V$3&"_"&$V$2 -> 2018_UnivMD_Maryland_86896_Dep01_20180711
AL16: =$F$2&"_Dep"&$V$3&"_"&$V$2 -> 2018_UnivMD_Maryland_86896_Dep01_20180711
AL17: =$F$2&"_Dep"&$V$3&"_"&$V$2 -> 2018_UnivMD_Maryland_86896_Dep01_20180711
AL18: =$F$2&"_Dep"&$V$3&"_"&$V$2 -> 2018_UnivMD_Maryland_86896_Dep01_20180711
AL19: =$F$2&"_Dep"&$V$3&"_"&$V$2 -> 2018_UnivMD_Maryland_86896_Dep01_20180711
AL20: =$F$2&"_Dep"&$V$3&"_"&$V$2 -> 2018_UnivMD_Maryland_86896_Dep01_20180711
AL21: =$F$2&"_Dep"&$V$3&"_"&$V$2 -> 2018_UnivMD_Maryland_86896_Dep01_20180711
AL22: =$F$2&"_Dep"&$V$3&"_"&$V$2 -> 2018_UnivMD_Maryland_86896_Dep01_20180711
AL23: =$F$2&"_Dep"&$V$3&"_"&$V$2 -> 2018_UnivMD_Maryland_86896_Dep01_20180711
AL24: =$F$2&"_Dep"&$V$3&"_"&$V$2 -> 2018_UnivMD_Maryland_86896_Dep01_20180711
AL25: =$F$2&"_Dep"&$V$3&"_"&$V$2 -> 2018_UnivMD_Maryland_86896_Dep01_20180711
... AL37: =$F$2&"_Dep"&$V$3&"_"&$V$2 -> 2018_UnivMD_Maryland_86896_Dep01_20180711

Sheet DECK SYNCHRONIZATIONS
B2: PROJECT | E2: ='META-DATA'!F2 -> 2018_UnivMD_Maryland_86896
B3: DEPLOYMENT | E3: ='META-DATA'!F3 -> 1
B8: BEGINNING DECK BANGS | I8: BEGINNING DECK BANGS
B9: DATE | D9: TIME | F9: TYPE OF SOUND | G9: UNIT NUMBERS | I9: DATE | K9: TIME | M9: TYPE OF SOUND | N9: UNIT NUMBERS
B10: 43292 | D10: 0.54761574 | F10: GLOBAL | G10: ALL | M10: GLOBAL
D11: 0.54778935 | F11: 5 Bang | M11: 5 Bang
D12: 0.54800926 | F12: 4 Bang | M12: 3 Bang
D13: 0.54824074 | F13: 3 Bang | M13: 2 Bang
D14: 0.54841435 | F14: 1 Bang | M14: 1 Bang
F15: GLOBAL | M15: GLOBAL
B17: END DECK BANGS | I17: END DECK BANGS
B18: DATE | D18: TIME | F18: TYPE OF SOUND | G18: UNIT NUMBERS | I18: DATE | K18: TIME | M18: TYPE OF SOUND | N18: UNIT NUMBERS
B19: 43334 | D19: XXX | F19: GLOBAL | G19: ALL | M19: GLOBAL
D20: 0.87782407 | F20: 5 Bang | M20: 5 Bang
D21: 0.878125 | F21: 4 Bang | M21: 4 Bang
D22: 0.87841435 | F22: 3 Bang | M22: 2 Bang
D23: 0.87859954 | F23: 1 Bang | M23: 1 Bang
D24: XXX | F24: GLOBAL | M24: GLOBAL
B30: BEGINNING DECK BANGS | I30: BEGINNING DECK BANGS
B31: DATE | D31: TIME | F31: TYPE OF SOUND | G31: UNIT NUMBERS | I31: DATE | K31: TIME | M31: TYPE OF SOUND | N31: UNIT NUMBERS
F32: GLOBAL | M32: GLOBAL
F33: 5 Bang | M33: 5 Bang
F34: 3 Bang | M34: 3 Bang
F35: 2 Bang | M35: 2 Bang
F36: 1 Bang | M36: 1 Bang
F37: GLOBAL | M37: GLOBAL
B39: END DECK BANGS | I39: END DECK BANGS
B40: DATE | D40: TIME | F40: TYPE OF SOUND | G40: UNIT NUMBERS | I40: DATE | K40: TIME | M40: TYPE OF SOUND | N40: UNIT NUMBERS
F41: GLOBAL | M41: GLOBAL
F42: 5 Bang | M42: 5 Bang
F43: 4 Bang | M43: 3 Bang
F44: 2 Bang | M44: 2 Bang
F45: 1 Bang | M45: 1 Bang
F46: GLOBAL | M46: GLOBAL
B52: BEGINNING DECK BANGS | I52: BEGINNING DECK BANGS
B53: DATE | D53: TIME | F53: TYPE OF SOUND | G53: UNIT NUMBERS | I53: DATE | K53: TIME | M53: TYPE OF SOUND | N53: UNIT NUMBERS
F54: GLOBAL | M54: GLOBAL
F55: 5 Bang | M55: 5 Bang
F56: 3 Bang | M56: 3 Bang
F57: 2 Bang | M57: 2 Bang
...

Sheet ARGOS REPORT
A3: PROJECT | D3: ='META-DATA'!F2 -> 2018_UnivMD_Maryland_86896
A4: DEPLOYMENT | D4: ='META-DATA'!F3 -> 1
A8: ARRAY ID | B8: SITE ID | C8: UNIT # | D8: DROP LAT Decimal Degrees | E8: DROP LON Decimal Degrees | F8: Burn Date Set | G8: Burn Time Set | H8: ARGOS # | I8: FREQUENCY
A9: ='META-DATA'!A31:C31 -> 0 | B9: ='META-DATA'!G31 -> 0 | C9: ='META-DATA'!C31 -> 0 | D9: ='META-DATA'!O31 -> 0 | E9: ='META-DATA'!P31 -> 0 | F9: ='META-DATA'!AH31 -> 0 | G9: ='META-DATA'!AI31 -> 0 | H9: ='META-DATA'!S31 -> 0 | I9: ='META-DATA'!U31 -> 0
A10: ='META-DATA'!A32:C32 -> 0 | B10: ='META-DATA'!G32 -> 0 | C10: ='META-DATA'!C32 -> 0 | D10: ='META-DATA'!O32 -> 0 | E10: ='META-DATA'!P32 -> 0 | F10: ='META-DATA'!AH32 -> 0 | G10: ='META-DATA'!AI32 -> 0 | H10: ='META-DATA'!S32 -> 0 | I10: ='META-DATA'!U32 -> 0
A11: ='META-DATA'!A33:C33 -> 0 | B11: ='META-DATA'!G33 -> 0 | C11: ='META-DATA'!C33 -> 0 | D11: ='META-DATA'!O33 -> 0 | E11: ='META-DATA'!P33 -> 0 | F11: ='META-DATA'!AH33 -> 0 | G11: ='META-DATA'!AI33 -> 0 | H11: ='META-DATA'!S33 -> 0 | I11: ='META-DATA'!U33 -> 0
A12: ='META-DATA'!A34:C34 -> 0 | B12: ='META-DATA'!G34 -> 0 | C12: ='META-DATA'!C34 -> 0 | D12: ='META-DATA'!O34 -> 0 | E12: ='META-DATA'!P34 -> 0 | F12: ='META-DATA'!AH34 -> 0 | G12: ='META-DATA'!AI34 -> 0 | H12: ='META-DATA'!S34 -> 0 | I12: ='META-DATA'!U34 -> 0
A13: ='META-DATA'!A35:C35 -> 0 | B13: ='META-DATA'!G35 -> 0 | C13: ='META-DATA'!C35 -> 0 | D13: ='META-DATA'!O35 -> 0 | E13: ='META-DATA'!P35 -> 0 | F13: ='META-DATA'!AH35 -> 0 | G13: ='META-DATA'!AI35 -> 0 | H13: ='META-DATA'!S35 -> 0 | I13: ='META-DATA'!U35 -> 0
A14: ='META-DATA'!A36:C36 -> 0 | B14: ='META-DATA'!G36 -> 0 | C14: ='META-DATA'!C36 -> 0 | D14: ='META-DATA'!O36 -> 0 | E14: ='META-DATA'!P36 -> 0 | F14: ='META-DATA'!AH36 -> 0 | G14: ='META-DATA'!AI36 -> 0 | H14: ='META-DATA'!S36 -> 0 | I14: ='META-DATA'!U36 -> 0
A15: ='META-DATA'!A24:C24 -> 0 | B15: ='META-DATA'!G24 -> 0 | C15: ='META-DATA'!C24 -> 0 | D15: ='META-DATA'!O24 -> 0 | E15: ='META-DATA'!P24 -> 0 | F15: ='META-DATA'!AH24 -> 0 | G15: ='META-DATA'!AI24 -> 0 | H15: ='META-DATA'!S24 -> 0 | I15: ='META-DATA'!U24 -> 0
A16: ='META-DATA'!A25:C25 -> 0 | B16: ='META-DATA'!G25 -> 0 | C16: ='META-DATA'!C25 -> 0 | D16: ='META-DATA'!O25 -> 0 | E16: ='META-DATA'!P25 -> 0 | F16: ='META-DATA'!AH25 -> 0 | G16: ='META-DATA'!AI25 -> 0 | H16: ='META-DATA'!S25 -> 0 | I16: ='META-DATA'!U25 -> 0
A17: ='META-DATA'!A26:C26 -> 0 | B17: ='META-DATA'!G26 -> 0 | C17: ='META-DATA'!C26 -> 0 | D17: ='META-DATA'!O26 -> 0 | E17: ='META-DATA'!P26 -> 0 | F17: ='META-DATA'!AH26 -> 0 | G17: ='META-DATA'!AI26 -> 0 | H17: ='META-DATA'!S26 -> 0 | I17: ='META-DATA'!U26 -> 0
A18: ='META-DATA'!A27:C27 -> 0 | B18: ='META-DATA'!G27 -> 0 | C18: ='META-DATA'!C27 -> 0 | D18: ='META-DATA'!O27 -> 0 | E18: ='META-DATA'!P27 -> 0 | F18: ='META-DATA'!AH27 -> 0 | G18: ='META-DATA'!AI27 -> 0 | H18: ='META-DATA'!S27 -> 0 | I18: ='META-DATA'!U27 -> 0
A19: ='META-DATA'!A28:C28 -> 0 | B19: ='META-DATA'!G28 -> 0 | C19: ='META-DATA'!C28 -> 0 | D19: ='META-DATA'!O28 -> 0 | E19: ='META-DATA'!P28 -> 0 | F19: ='META-DATA'!AH28 -> 0 | G19: ='META-DATA'!AI28 -> 0 | H19: ='META-DATA'!S28 -> 0 | I19: ='META-DATA'!U28 -> 0
A20: ='META-DATA'!A30:C30 -> 0 | B20: ='META-DATA'!G30 -> 0 | C20: ='META-DATA'!C30 -> 0 | D20: ='META-DATA'!O30 -> 0 | E20: ='META-DATA'!P30 -> 0 | F20: ='META-DATA'!AH30 -> 0 | G20: ='META-DATA'!AI30 -> 0 | H20: ='META-DATA'!S30 -> 0 | I20: ='META-DATA'!U30 -> 0
A21: ='META-DATA'!A19:C19 -> 0 | B21: ='META-DATA'!G19 -> 0 | C21: ='META-DATA'!C19 -> 0 | D21: ='META-DATA'!O19 -> 0 | E21: ='META-DATA'!P19 -> 0 | F21: ='META-DATA'!AH19 -> 0 | G21: ='META-DATA'!AI19 -> 0 | H21: ='META-DATA'!S19 -> 0 | I21: ='META-DATA'!U19 -> 0
A22: ='META-DATA'!A20:C20 -> 0 | B22: ='META-DATA'!G20 -> 0 | C22: ='META-DATA'!C20 -> 0 | D22: ='META-DATA'!O20 -> 0 | E22: ='META-DATA'!P20 -> 0 | F22: ='META-DATA'!AH20 -> 0 | G22: ='META-DATA'!AI20 -> 0 | H22: ='META-DATA'!S20 -> 0 | I22: ='META-DATA'!U20 -> 0
A23: ='META-DATA'!A21:C21 -> 0 | B23: ='META-DATA'!G21 -> 0 | C23: ='META-DATA'!C21 -> 0 | D23: ='META-DATA'!O21 -> 0 | E23: ='META-DATA'!P21 -> 0 | F23: ='META-DATA'!AH21 -> 0 | G23: ='META-DATA'!AI21 -> 0 | H23: ='META-DATA'!S21 -> 0 | I23: ='META-DATA'!U21 -> 0
A24: ='META-DATA'!A22:C22 -> 0 | B24: ='META-DATA'!G22 -> 0 | C24: ='META-DATA'!C22 -> 0 | D24: ='META-DATA'!O22 -> 0 | E24: ='META-DATA'!P22 -> 0 | F24: ='META-DATA'!AH22 -> 0 | G24: ='META-DATA'!AI22 -> 0 | H24: ='META-DATA'!S22 -> 0 | I24: ='META-DATA'!U22 -> 0
A25: ='META-DATA'!A23:C23 -> 0 | B25: ='META-DATA'!G23 -> 0 | C25: ='META-DATA'!C23 -> 0 | D25: ='META-DATA'!O23 -> 0 | E25: ='META-DATA'!P23 -> 0 | F25: ='META-DATA'!AH23 -> 0 | G25: ='META-DATA'!AI23 -> 0 | H25: ='META-DATA'!S23 -> 0 | I25: ='META-DATA'!U23 -> 0
A26: ='META-DATA'!A16:C16 -> 0 | B26: ='META-DATA'!G16 -> 0 | C26: ='META-DATA'!C16 -> 0 | D26: ='META-DATA'!O16 -> 0 | E26: ='META-DATA'!P16 -> 0 | F26: ='META-DATA'!AH16 -> 0 | G26: ='META-DATA'!AI16 -> 0 | H26: ='META-DATA'!S16 -> 0 | I26: ='META-DATA'!U16 -> 0
A27: ='META-DATA'!A17:C17 -> 0 | B27: ='META-DATA'!G17 -> 0 | C27: ='META-DATA'!C17 -> 0 | D27: ='META-DATA'!O17 -> 0 | E27: ='META-DATA'!P17 -> 0 | F27: ='META-DATA'!AH17 -> 0 | G27: ='META-DATA'!AI17 -> 0 | H27: ='META-DATA'!S17 -> 0 | I27: ='META-DATA'!U17 -> 0
A28: ='META-DATA'!A18:C18 -> 0 | B28: ='META-DATA'!G18 -> 0 | C28: ='META-DATA'!C18 -> 0 | D28: ='META-DATA'!O18 -> 0 | E28: ='META-DATA'!P18 -> 0 | F28: ='META-DATA'!AH18 -> 0 | G28: ='META-DATA'!AI18 -> 0 | H28: ='META-DATA'!S18 -> 0 | I28: ='META-DATA'!U18 -> 0
A29: ='META-DATA'!A10:C10 -> UMD | B29: ='META-DATA'!G10 -> M1 | C29: ='META-DATA'!C10 -> 168 | D29: ='META-DATA'!O10 -> 38.37031 | E29: ='META-DATA'!P10 -> -74.75384 | F29: ='META-DATA'!AH10 -> 43388 | G29: ='META-DATA'!AI10 -> 0.55084491 | H29: ='META-DATA'!S10 -> 134121 | I29: ='META-DATA'!U10 -> 0
A30: ='META-DATA'!A11:C11 -> UMD | B30: ='META-DATA'!G11 -> M2 | C30: ='META-DATA'!C11 -> 89 | D30: ='META-DATA'!O11 -> 38.35305 | E30: ='META-DATA'!P11 -> -74.7309 | F30: ='META-DATA'!AH11 -> 43388 | G30: ='META-DATA'!AI11 -> 0.59321759 | H30: ='META-DATA'!S11 -> 134136 | I30: ='META-DATA'!U11 -> 0
A31: ='META-DATA'!A12:C12 -> UMD | B31: ='META-DATA'!G12 -> M3 | C31: ='META-DATA'!C12 -> 188 | D31: ='META-DATA'!O12 -> 38.33452 | E31: ='META-DATA'!P12 -> -74.75369 | F31: ='META-DATA'!AH12 -> 43388 | G31: ='META-DATA'!AI12 -> 0.63559028 | H31: ='META-DATA'!S12 -> 134126 | I31: ='META-DATA'!U12 -> 0
A32: ='META-DATA'!A13:C13 -> UMD | B32: ='META-DATA'!G13 -> M4 | C32: ='META-DATA'!C13 -> 142 | D32: ='META-DATA'!O13 -> 38.35279 | E32: ='META-DATA'!P13 -> -74.77635 | F32: ='META-DATA'!AH13 -> 43388 | G32: ='META-DATA'!AI13 -> 0.50847222 | H32: ='META-DATA'!S13 -> 134132 | I32: ='META-DATA'!U13 -> 0
A33: ='META-DATA'!A14:C14 -> 0 | B33: ='META-DATA'!G14 -> 0 | C33: ='META-DATA'!C14 -> 0 | D33: ='META-DATA'!O14 -> 0 | E33: ='META-DATA'!P14 -> 0 | F33: ='META-DATA'!AH14 -> 0 | G33: ='META-DATA'!AI14 -> 0 | H33: ='META-DATA'!S14 -> 0 | I33: ='META-DATA'!U14 -> 0
A34: ='META-DATA'!A15:C15 -> 0 | B34: ='META-DATA'!G15 -> 0 | C34: ='META-DATA'!C15 -> 0 | D34: ='META-DATA'!O15 -> 0 | E34: ='META-DATA'!P15 -> 0 | F34: ='META-DATA'!AH15 -> 0 | G34: ='META-DATA'!AI15 -> 0 | H34: ='META-DATA'!S15 -> 0 | I34: ='META-DATA'!U15 -> 0
A35: ='META-DATA'!A37:C124 -> #VALUE! | B35: ='META-DATA'!#REF! -> #REF! | C35: ='META-DATA'!#REF! -> #REF! | D35: ='META-DATA'!#REF! -> #REF! | E35: ='META-DATA'!#REF! -> #REF! | F35: ='META-DATA'!#REF! -> #REF! | G35: ='META-DATA'!#REF! -> #REF! | H35: ='META-DATA'!#REF! -> #REF! | I35: ='META-DATA'!#REF! -> #REF!
A36: ='META-DATA'!#REF! -> #REF! | B36: ='META-DATA'!#REF! -> #REF! | C36: ='META-DATA'!#REF! -> #REF! | D36: ='META-DATA'!#REF! -> #REF! | E36: ='META-DATA'!#REF! -> #REF! | F36: ='META-DATA'!#REF! -> #REF! | G36: ='META-DATA'!#REF! -> #REF! | H36: ='META-DATA'!#REF! -> #REF! | I36: ='META-DATA'!#REF! -> #REF!
A37: ='META-DATA'!#REF! -> #REF! | B37: ='META-DATA'!#REF! -> #REF! | C37: ='META-DATA'!#REF! -> #REF! | D37: ='META-DATA'!#REF! -> #REF! | E37: ='META-DATA'!#REF! -> #REF! | F37: ='META-DATA'!#REF! -> #REF! | G37: ='META-DATA'!#REF! -> #REF! | H37: ='META-DATA'!#REF! -> #REF! | I37: ='META-DATA'!#REF! -> #REF!
A38: ='META-DATA'!#REF! -> #REF! | B38: ='META-DATA'!#REF! -> #REF! | C38: ='META-DATA'!#REF! -> #REF! | D38: ='META-DATA'!#REF! -> #REF! | E38: ='META-DATA'!#REF! -> #REF! | F38: ='META-DATA'!#REF! -> #REF! | G38: ='META-DATA'!#REF! -> #REF! | H38: ='META-DATA'!#REF! -> #REF! | I38: ='META-DATA'!#REF! -> #REF!
A39: ='META-DATA'!#REF! -> #REF! | B39: ='META-DATA'!#REF! -> #REF! | C39: ='META-DATA'!#REF! -> #REF! | D39: ='META-DATA'!#REF! -> #REF! | E39: ='META-DATA'!#REF! -> #REF! | F39: ='META-DATA'!#REF! -> #REF! | G39: ='META-DATA'!#REF! -> #REF! | H39: ='META-DATA'!#REF! -> #REF! | I39: ='META-DATA'!#REF! -> #REF!
A40: ='META-DATA'!#REF! -> #REF! | B40: ='META-DATA'!#REF! -> #REF! | C40: ='META-DATA'!#REF! -> #REF! | D40: ='META-DATA'!#REF! -> #REF! | E40: ='META-DATA'!#REF! -> #REF! | F40: ='META-DATA'!#REF! -> #REF! | G40: ='META-DATA'!#REF! -> #REF! | H40: ='META-DATA'!#REF! -> #REF! | I40: ='META-DATA'!#REF! -> #REF!
A41: ='META-DATA'!#REF! -> #REF! | B41: ='META-DATA'!#REF! -> #REF! | C41: ='META-DATA'!#REF! -> #REF! | D41: ='META-DATA'!#REF! -> #REF! | E41: ='META-DATA'!#REF! -> #REF! | F41: ='META-DATA'!#REF! -> #REF! | G41: ='META-DATA'!#REF! -> #REF! | H41: ='META-DATA'!#REF! -> #REF! | I41: ='META-DATA'!#REF! -> #REF!
A42: ='META-DATA'!#REF! -> #REF! | B42: ='META-DATA'!#REF! -> #REF! | C42: ='META-DATA'!#REF! -> #REF! | D42: ='META-DATA'!#REF! -> #REF! | E42: ='META-DATA'!#REF! -> #REF! | F42: ='META-DATA'!#REF! -> #REF! | G42: ='META-DATA'!#REF! -> #REF! | H42: ='META-DATA'!#REF! -> #REF! | I42: ='META-DATA'!#REF! -> #REF!

Sheet DATA TABLE FOR EXPORT
A1: arrayName | B1: recorderDeviceType | C1: containerID | D1: recordMediumType | E1: recordMediumMasterBRPID | F1: recordMediumSlaveBRPID | G1: nominalID | H1: [FREQ, kHz] | I1: samplingRate_Hz | J1: highPassSetting_Hz | K1: lowPassSetting_Hz | L1: gain_dB | M1: dutyCycleOnDuration_secs | N1: dutyCycleOffDuration_secs | O1: latitudeDeployed_DecDeg | P1: longitudeDeployed_DecDeg | Q1: deploymentDepth_Meters | R1: depthOrElevationDeterminationMethod | S1: argosID | T1: xeosID | U1: [FREQUENCY] | V1: recordStartDate | W1: recordStartTime | X1: timeZoneOfRecordStart | Y1: deployDate | Z1: deployTime | AA1: timeZoneOfDeploymentSite | AB1: recoveryDate | AC1: recoveryTime | AD1: timeZoneOfRecoverySite | AE1: recordStopDate | AF1: recordStopTime | AG1: timeZoneOfRecordStop | AH1: [Burn Date Set] | AI1: [Burn Time Set] | AJ1: [Burn TIME ZONE] | AK1: notes | AL1: KEY_deployment_ID | AM1: databaseEntrySource
A2: ='META-DATA'!A10 -> UMD | B2: ='META-DATA'!B10 -> V2.5 Popup | C2: ='META-DATA'!C10 -> 168 | D2: ='META-DATA'!D10 -> CompactFlash | E2: ='META-DATA'!E10 -> 3164 | F2: ='META-DATA'!F10 -> 0 | G2: ='META-DATA'!G10 -> M1 | H2: ='META-DATA'!H10 -> 16 | ... U2: ='META-DATA'!U10 -> 0 | V2: =IF('META-DATA'!V10="",47484,'META-DATA'!V10) -> 43292 | W2: ='META-DATA'!W10 -> 0.52575231 | X2: ='META-DATA'!X10 -> 0 | Y2: =IF('META-DATA'!Y10="",47484,'META-DATA'!Y10) -> 43293 | Z2: ='META-DATA'!Z10 -> 0.71041667 | AA2: ='META-DATA'!AA10 -> 0 | AB2: =IF('META-DATA'!AB10="",47484,'META-DATA'!AB10) -> 43333 | AC2: ='META-DATA'!AC10 -> 0.52916667 | AD2: ='META-DATA'!AD10 -> 0 | AE2: =IF('META-DATA'!AE10="",47484,'META-DATA'!AE10) -> 47484 | AF2: ='META-DATA'!AF10 -> 0 | AG2: ='META-DATA'!AG10 -> 0 | AH2: =IF('META-DATA'!AH10="",47484,'META-DATA'!AH10) -> 43388 | AI2: ='META-DATA'!AI10 -> 0.55084491 | AJ2: ='META-DATA'!AJ10 -> 0 | AK2: =IF('META-DATA'!AK10="","",'META-DATA'!AK10) | AL2: ='META-DATA'!AL10 -> 2018_UnivMD_Maryland_86896_Dep01_20180711 | AM2: =IF('META-DATA'!$J$4="frc29","Channell_Fred_frc29",'META-DATA'!$J$4) -> Channell_Fred_frc29
A3: ='META-DATA'!A11 -> UMD | B3: ='META-DATA'!B11 -> V2.5 Popup | C3: ='META-DATA'!C11 -> 89 | D3: ='META-DATA'!D11 -> CompactFlash | E3: ='META-DATA'!E11 -> 3156 | F3: ='META-DATA'!F11 -> 0 | G3: ='META-DATA'!G11 -> M2 | H3: ='META-DATA'!H11 -> 16 | ... U3: ='META-DATA'!U11 -> 0 | V3: =IF('META-DATA'!V11="",47484,'META-DATA'!V11) -> 43292 | W3: ='META-DATA'!W11 -> 0.53015046 | X3: ='META-DATA'!X11 -> 0 | Y3: =IF('META-DATA'!Y11="",47484,'META-DATA'!Y11) -> 43293 | Z3: ='META-DATA'!Z11 -> 0.71805556 | AA3: ='META-DATA'!AA11 -> 0 | AB3: =IF('META-DATA'!AB11="",47484,'META-DATA'!AB11) -> 43333 | AC3: ='META-DATA'!AC11 -> 0.55277778 | AD3: ='META-DATA'!AD11 -> 0 | AE3: =IF('META-DATA'!AE11="",47484,'META-DATA'!AE11) -> 47484 | AF3: ='META-DATA'!AF11 -> 0 | AG3: ='META-DATA'!AG11 -> 0 | AH3: =IF('META-DATA'!AH11="",47484,'META-DATA'!AH11) -> 43388 | AI3: ='META-DATA'!AI11 -> 0.59321759 | AJ3: ='META-DATA'!AJ11 -> 0 | AK3: =IF('META-DATA'!AK11="","",'META-DATA'!AK11) -> CTD# S7958 | AL3: ='META-DATA'!AL11 -> 2018_UnivMD_Maryland_86896_Dep01_20180711 | AM3: =IF('META-DATA'!$J$4="frc29","Channell_Fred_frc29",'META-DATA'!$J$4) -> Channell_Fred_frc29
A4: ='META-DATA'!A12 -> UMD | B4: ='META-DATA'!B12 -> V2.5 Popup | C4: ='META-DATA'!C12 -> 188 | D4: ='META-DATA'!D12 -> CompactFlash | E4: ='META-DATA'!E12 -> 3168 | F4: ='META-DATA'!F12 -> 0 | G4: ='META-DATA'!G12 -> M3 | H4: ='META-DATA'!H12 -> 16 | ... U4: ='META-DATA'!U12 -> 0 | V4: =IF('META-DATA'!V12="",47484,'META-DATA'!V12) -> 43292 | W4: ='META-DATA'!W12 -> 0.53385417 | X4: ='META-DATA'!X12 -> 0 | Y4: =IF('META-DATA'!Y12="",47484,'META-DATA'!Y12) -> 43293 | Z4: ='META-DATA'!Z12 -> 0.69583333 | AA4: ='META-DATA'!AA12 -> 0 | AB4: =IF('META-DATA'!AB12="",47484,'META-DATA'!AB12) -> 43333 | AC4: ='META-DATA'!AC12 -> 0.48125 | AD4: ='META-DATA'!AD12 -> 0 | AE4: =IF('META-DATA'!AE12="",47484,'META-DATA'!AE12) -> 47484 | AF4: ='META-DATA'!AF12 -> 0 | AG4: ='META-DATA'!AG12 -> 0 | AH4: =IF('META-DATA'!AH12="",47484,'META-DATA'!AH12) -> 43388 | AI4: ='META-DATA'!AI12 -> 0.63559028 | AJ4: ='META-DATA'!AJ12 -> 0 | AK4: =IF('META-DATA'!AK12="","",'META-DATA'!AK12) -> CTD# S8044 SURFACED EARLY, RECOVERED ON RETRIEVAL DAY | AL4: ='META-DATA'!AL12 -> 2018_UnivMD_Maryland_86896_Dep01_20180711 | AM4: =IF('META-DATA'!$J$4="frc29","Channell_Fred_frc29",'META-DATA'!$J$4) -> Channell_Fred_frc29
A5: ='META-DATA'!A13 -> UMD | B5: ='META-DATA'!B13 -> V2.5 Popup | C5: ='META-DATA'!C13 -> 142 | D5: ='META-DATA'!D13 -> CompactFlash | E5: ='META-DATA'!E13 -> 3104 | F5: ='META-DATA'!F13 -> 0 | G5: ='META-DATA'!G13 -> M4 | H5: ='META-DATA'!H13 -> 16 | ... U5: ='META-DATA'!U13 -> 0 | V5: =IF('META-DATA'!V13="",47484,'META-DATA'!V13) -> 43292 | W5: ='META-DATA'!W13 -> 0.52060185 | X5: ='META-DATA'!X13 -> 0 | Y5: =IF('META-DATA'!Y13="",47484,'META-DATA'!Y13) -> 43293 | Z5: ='META-DATA'!Z13 -> 0.70347222 | AA5: ='META-DATA'!AA13 -> 0 | AB5: =IF('META-DATA'!AB13="",47484,'META-DATA'!AB13) -> 43333 | AC5: ='META-DATA'!AC13 -> 0.57430556 | AD5: ='META-DATA'!AD13 -> 0 | AE5: =IF('META-DATA'!AE13="",47484,'META-DATA'!AE13) -> 47484 | AF5: ='META-DATA'!AF13 -> 0 | AG5: ='META-DATA'!AG13 -> 0 | AH5: =IF('META-DATA'!AH13="",47484,'META-DATA'!AH13) -> 43388 | AI5: ='META-DATA'!AI13 -> 0.50847222 | AJ5: ='META-DATA'!AJ13 -> 0 | AK5: =IF('META-DATA'!AK13="","",'META-DATA'!AK13) -> CTD# S7959 | AL5: ='META-DATA'!AL13 -> 2018_UnivMD_Maryland_86896_Dep01_20180711 | AM5: =IF('META-DATA'!$J$4="frc29","Channell_Fred_frc29",'META-DATA'!$J$4) -> Channell_Fred_frc29

Sheet GENERAL NOTES

Sheet DICTIONARY

Sheet DATA TABLE w FM
A1: ARRAY ID | B1: Recorder Type | C1: UNIT # | D1: Medium Type | E1: DRIVE # 1 | F1: DRIVE # 2 | G1: SITE ID | H1: FREQ, kHz | I1: FREQ Hz | J1: Filter, High Pass Hz | K1: Filter, Low Pass Hz | L1: Gain dB | M1: DUTY CYCLE seconds on | N1: DUTY CYCLE seconds off | O1: DROP LAT Decimal Degrees | P1: DROP LON Decimal Degrees | Q1: DEPTH IN METERS | R1: SOURCE FOR DEPTH | S1: ARGOS # | T1: XEOS ID | U1: FREQUENCY | V1: RECORD START DATE | W1: RECORD START TIME (<1sec accuracy) | X1: RECORD START TIME ZONE | Y1: DROP DATE | Z1: DROP TIME (1min accuracy) | AA1: Drop TIME ZONE | AB1: RETRIEVAL DATE | AC1: ON DECK TIME (5min accuracy) | AD1: Retrieval TIME ZONE | AE1: DISCONNECT DATE | AF1: DISCONNECT TIME (1min accuracy) | AG1: Shut Down TIME ZONE | AH1: Burn Date Set | AI1: Burn Time Set | AJ1: Burn TIME ZONE | AK1: COMMENT | AL1: PROJECT NAME | AM1: DATA ENTRY NETID
A2: arrayName | B2: recorderDeviceType | C2: containerID | D2: recordMediumType | E2: recordMediumMasterBRPID | F2: recordMediumSlaveBRPID | G2: nominalID | H2: [FREQ, kHz] | I2: samplingRate_Hz | J2: highPassSetting_Hz | K2: lowPassSetting_Hz | L2: gain_dB | M2: dutyCycleOnDuration_secs | N2: dutyCycleOffDuration_secs | O2: latitudeDeployed_DecDeg | P2: longitudeDeployed_DecDeg | Q2: deploymentDepth_Meters | R2: depthOrElevationDeterminationMethod | S2: argosID | T2: xeosID | U2: [FREQUENCY] | V2: recordStartDate | W2: recordStartTime | X2: timeZoneOfRecordStart | Y2: deployDate | Z2: deployTime | AA2: timeZoneOfDeploymentSite | AB2: recoveryDate | AC2: recoveryTime | AD2: timeZoneOfRecoverySite | AE2: recordStopDate | AF2: recordStopTime | AG2: timeZoneOfRecordStop | AH2: [Burn Date Set] | AI2: [Burn Time Set] | AJ2: [Burn TIME ZONE] | AK2: notes | AL2: KEY_deployment_ID | AM2: databaseEntrySource
A3: ='META-DATA'!A10 -> UMD | B3: ='META-DATA'!B10 -> V2.5 Popup | C3: ='META-DATA'!C10 -> 168 | D3: ='META-DATA'!D10 -> CompactFlash | E3: ='META-DATA'!E10 -> 3164 | F3: ='META-DATA'!F10 -> 0 | G3: ='META-DATA'!G10 -> M1 | H3: ='META-DATA'!H10 -> 16 | ... U3: ='META-DATA'!U10 -> 0 | V3: =IF('META-DATA'!V10="",47484,'META-DATA'!V10) -> 43292 | W3: ='META-DATA'!W10 -> 0.52575231 | X3: ='META-DATA'!X10 -> 0 | Y3: =IF('META-DATA'!Y10="",47484,'META-DATA'!Y10) -> 43293 | Z3: ='META-DATA'!Z10 -> 0.71041667 | AA3: ='META-DATA'!AA10 -> 0 | AB3: =IF('META-DATA'!AB10="",47484,'META-DATA'!AB10) -> 43333 | AC3: ='META-DATA'!AC10 -> 0.52916667 | AD3: ='META-DATA'!AD10 -> 0 | AE3: =IF('META-DATA'!AE10="",47484,'META-DATA'!AE10) -> 47484 | AF3: ='META-DATA'!AF10 -> 0 | AG3: ='META-DATA'!AG10 -> 0 | AH3: =IF('META-DATA'!AH10="",47484,'META-DATA'!AH10) -> 43388 | AI3: ='META-DATA'!AI10 -> 0.55084491 | AJ3: ='META-DATA'!AJ10 -> 0 | AK3: =IF('META-DATA'!AK10="","",'META-DATA'!AK10) | AL3: ='META-DATA'!AL10 -> 2018_UnivMD_Maryland_86896_Dep01_20180711 | AM3: ='META-DATA'!$F$4 -> FRC29
